<?xml version="1.0"?>
<robot name="trimod" xmlns:xacro="http://www.ros.org/wiki/xacro">

  <xacro:property name="scale" value="0.1"/>
  <xacro:property name="fingerDepth" value="0.2"/>
  <xacro:property name="link0r" value="0.2"/>
  <xacro:property name="link0h" value="0.1"/>
  <xacro:property name="link1a" value="0.6"/>
  <xacro:property name="link2a" value="0.4"/>
  <xacro:property name="effort" value="50"/>
  <xacro:property name="jdamping" value="0.03"/>
  <xacro:property name="jfriction" value="3.0"/>
<!--<xacro:property name="interface" value="PositionJointInterface"/>-->
  <xacro:property name="interface" value="EffortJointInterface"/>
  <xacro:property name="mass" value="1"/>

  <macro name="finger" params="name parent *origin">

    <link name="${name}_base">
      <visual>
        <origin rpy="0 0 0" xyz="0 0 0"/>
        <geometry>
          <cylinder length="0.01" radius="0.02"/>
        </geometry>
        <material name="blue">
          <color rgba="0 0 .8 1"/>
        </material>
      </visual>
      <collision>
        <origin rpy="0 0 0" xyz="0 0 0"/>
        <geometry>
          <cylinder length="0.01" radius="0.04"/>
        </geometry>
      </collision>
      <inertial>
        <origin rpy="0 0 0" xyz="0 0 0"/>
        <mass value="${mass/4}"/>
        <box_inertia m="${mass/4}" x="0.01" y="0.01" z="0.01"/>
      </inertial>
    </link>

    <link name="${name}_link0">
      <visual>
        <origin rpy="0 0 0" xyz="0 0 0"/>
        <geometry>
          <mesh filename="package://trimod_gripper/meshes/Link0.stl" scale="${scale} ${scale} ${scale}"/>
        </geometry>
      </visual>

      <collision>
        <origin rpy="0 0 0" xyz="0 0 0"/>
        <geometry>
          <mesh filename="package://trimod_gripper/meshes/Link0_convex.stl" scale="${scale} ${scale} ${scale}"/>
        </geometry>
        <contact_coefficients kd="100000.0" kp="100000.0" mu="10.0"/>
      </collision>

      <inertial>
        <origin rpy="0 0 0" xyz="${fingerDepth*scale*0.5} 0.000000 ${fingerDepth*scale*0.5}"/>
        <mass value="${mass/4}"/>
        <box_inertia m="${mass/4}" x="${link0r*scale}" y="${fingerDepth*scale}" z="${0.2*scale}"/>
      </inertial>
    </link>

    <link name="${name}_link1">
      <visual>
        <origin rpy="0 0 0" xyz="0 0 0"/>
        <geometry>
          <mesh filename="package://trimod_gripper/meshes/Link1.stl" scale="${scale} ${scale} ${scale}"/>
        </geometry>
        <material name="blue">
          <color rgba="0 0 .8 1"/>
        </material>

      </visual>

      <collision>
        <origin rpy="0 0 0" xyz="0 0 0"/>
        <geometry>
          <mesh filename="package://trimod_gripper/meshes/Link1_convex.stl" scale="${scale} ${scale} ${scale}"/>
        </geometry>
        <contact_coefficients kd="100000.0" kp="100000.0" mu="10.0"/>
      </collision>

      <inertial>
        <origin rpy="0 0 0" xyz="${link1a*scale*0.5} 0.000000 0.000000"/>
        <mass value="${mass/4}"/>
        <box_inertia m="${mass/4}" x="${link1a*scale}" y="${fingerDepth*scale}" z="${fingerDepth*scale}"/>
      </inertial>
    </link>

    <link name="${name}_link2">
      <visual>
        <origin rpy="0 0 0" xyz="0 0 0"/>
        <geometry>
          <mesh filename="package://trimod_gripper/meshes/Link2.stl" scale="${scale} ${scale} ${scale}"/>
        </geometry>
        <material name="blue">
          <color rgba="0 0 .8 1"/>
        </material>

      </visual>

      <collision_sphere radius="${link0r*scale*0.5}" rpy="0 0 0" xyz="${link2a*scale} 0 0"/>

      <inertial>
        <origin rpy="0 0 0" xyz="${link2a*scale*0.5} 0.000000 0.000000"/>
        <mass value="${mass/4}"/>
        <box_inertia m="${mass/4}" x="${link2a*scale}" y="${fingerDepth*scale}" z="${fingerDepth*scale}"/>
      </inertial>
    </link>

    <gazebo reference="${name}_link2">
      <kp>10000000000</kp>
      <kd>0.01</kd>
      <mu1>Inf</mu1>
      <mu2>Inf</mu2>

      <!--
      <sensor name="${name}_fixed_jaw_contact_sensor" type="contact">
        <always_on>true</always_on>
        <update_rate>20</update_rate>
        <contact>

          <collision>${name}_link2_collision</collision>
        </contact>
        <plugin filename="libgazebo_ros_bumper.so" name="${name}_fixed_jaw_bumper">
          <bumperTopicName>${name}_sensor_state</bumperTopicName>
          <frameName>${name}_link2</frameName>
        </plugin>
      </sensor>
    -->


    </gazebo>

<!-- JOINTS -->

    <joint name="${name}_joint_base" type="fixed">
      <parent link="${parent}"/>
      <child link="${name}_base"/>
      <insert_block name="origin"/>
    </joint>

    <joint name="${name}_joint_palm" type="revolute">
      <parent link="${name}_base"/>
      <child link="${name}_link0"/>
      <origin rpy="0 0 0" xyz="0 0 0"/>
      <axis xyz="0 0 1"/>
      <limit effort="${effort}" lower="${-90 * M_PI / 180}" upper="${90 * M_PI / 180}" velocity="100"/>
      <dynamics damping="${jdamping}" friction="${jfriction}"/>
    </joint>

    <joint name="${name}_joint_proximal" type="revolute">
      <parent link="${name}_link0"/>
      <child link="${name}_link1"/>
      <origin rpy="${M_PI/2} -${M_PI/2} 0" xyz="${link0r*scale} 0 ${link0h*scale}"/>
      <axis xyz="0 0 1"/>
      <limit effort="${effort}" lower="${-90 * M_PI / 180}" upper="${50 * M_PI / 180}" velocity="100"/>
      <dynamics damping="${jdamping}" friction="${jfriction}"/>
    </joint>

    <joint name="${name}_joint_distal" type="revolute">
      <parent link="${name}_link1"/>
      <child link="${name}_link2"/>
      <origin rpy="0 0 0" xyz="${link1a*scale} 0 0"/>
      <axis xyz="0 0 1"/>
      <limit effort="${effort}" lower="${-90 * M_PI / 180}" upper="${90 * M_PI / 180}" velocity="100"/>
      <dynamics damping="${jdamping}" friction="${jfriction}"/>
    </joint>

<!-- TRANSMISSIONS -->
    <transmission name="${name}_transmission_joint_palm">
      <type>transmission_interface/SimpleTransmission</type>
      <joint name="${name}_joint_palm">

        <hardwareInterface>${interface}</hardwareInterface>
      </joint>
      <actuator name="${name}_motor_joint_palm">

        <hardwareInterface>${interface}</hardwareInterface>
        <mechanicalReduction>1</mechanicalReduction>
      </actuator>
    </transmission>

    <transmission name="${name}_transmission_joint_proximal">
      <type>transmission_interface/SimpleTransmission</type>
      <joint name="${name}_joint_proximal">

        <hardwareInterface>${interface}</hardwareInterface>
      </joint>
      <actuator name="${name}_motor_joint_proximal">

        <hardwareInterface>${interface}</hardwareInterface>
        <mechanicalReduction>1</mechanicalReduction>
      </actuator>
    </transmission>

    <transmission name="${name}_transmission_joint_distal">
      <type>transmission_interface/SimpleTransmission</type>
      <joint name="${name}_joint_distal">

        <hardwareInterface>${interface}</hardwareInterface>
      </joint>
      <actuator name="${name}_motor_joint_distal">

        <hardwareInterface>${interface}</hardwareInterface>
        <mechanicalReduction>1</mechanicalReduction>
      </actuator>
    </transmission>

  </macro>

</robot>
